Sending build context to Docker daemon  21.75MB
Step 1/5 : FROM nciccbr/ccrgb_fusioncatcher:v1.0
 ---> 0ef4f2e06a88
Step 2/5 : ENV TAG="v1.1"
 ---> Using cache
 ---> c7348c686df0
Step 3/5 : WORKDIR /opt2
 ---> Using cache
 ---> 3633495c8dc2
Step 4/5 : COPY fusioncatcher_getdata.sh /opt2
 ---> Using cache
 ---> 893b66a483b3
Step 5/5 : RUN mkdir -p /opt2/data && 	cd /opt2/data && 	chmod a+x /opt2/fusioncatcher_getdata.sh && 	fusioncatcher_getdata.sh
 ---> Running in 6aa1a702d1e0
[91mUSING fusioncatcher CONDA env!
[0m[91mWARNING: Cannot restart automatically because the previous log file '/opt2/data/fusioncatcher-build.log' cannot be found!
The workflow will be restarted from the beginning with step 1!
[0mPython version: 2.7.15 | packaged by conda-forge | (default, Mar  4 2020, 16:23:03) 
[GCC 7.3.0]
Python executable: /opt2/conda/envs/fusioncatcher/bin/python
1.76
[91m
gzip: [0m[91mstdout: No space left on device
[0mDownloading the genome of organism 'homo_sapiens' from Ensembl!
230 Login successful.
Downloading: /pub/current_fasta//homo_sapiens/dna/Homo_sapiens.GRCh38.dna.chromosome.MT.fa.gz
Downloading: /pub/current_fasta//homo_sapiens/dna/Homo_sapiens.GRCh38.dna.primary_assembly.fa.gz
Executing:   gzip -d -f -c '/opt2/data/Homo_sapiens.GRCh38.dna.chromosome.MT.fa.gz' > '/opt2/data/Homo_sapiens.GRCh38.dna.chromosome.MT.fa'
Executing:   gzip -d -f -c '/opt2/data/Homo_sapiens.GRCh38.dna.primary_assembly.fa.gz' > '/opt2/data/Homo_sapiens.GRCh38.dna.primary_assembly.fa'
  * chromosome 1 has length 248956422
  * chromosome 10 has length 133797422
  * chromosome 11 has length 135086622
  * chromosome 12 has length 133275309
  * chromosome 13 has length 114364328
  * chromosome 14 has length 107043718
  * chromosome 15 has length 101991189
  * chromosome 16 has length 90338345
  * chromosome 17 has length 83257441
  * chromosome 18 has length 78122254
230 Login successful.
[91mTraceback (most recent call last):
  File "/opt2/conda/envs/fusioncatcher/bin/get_gtf.py", line 164, in <module>
[0m[91m    fod.write(file_content)
IOError: [Errno 28] No space left on device
[0mLog of the pipeline:
--------------------------------------------------------------------------------
Starting execution with step 1.
////////////////////////////////////////////////////////////////////////////////
  Running: step = 1   Time: 17:56   Date: 2022-12-06 (elapsed time: 0d:0h:0m)
\\\\\\\\\\\\\\\\\\\\\\\\\\\\\\\\\\\\\\\\\\\\\\\\\\\\\\\\\\\\\\\\\\\\\\\\\\\\\\\\
==> Current working directory: '/opt2/data'
python_version.py
--------------------------------------------------------------------------------
+-->EXECUTING...
--------------------------------------------------------------------------------
==> Execution time: 0 day(s), 0 hour(s), 0 minute(s), and 0 second(s)
////////////////////////////////////////////////////////////////////////////////
  Running: step = 2   Time: 17:56   Date: 2022-12-06 (elapsed time: 0d:0h:0m)
\\\\\\\\\\\\\\\\\\\\\\\\\\\\\\\\\\\\\\\\\\\\\\\\\\\\\\\\\\\\\\\\\\\\\\\\\\\\\\\\
==> Current working directory: '/opt2/data'
biopython_version.py
--------------------------------------------------------------------------------
+-->EXECUTING...
--------------------------------------------------------------------------------
==> Execution time: 0 day(s), 0 hour(s), 0 minute(s), and 0 second(s)
////////////////////////////////////////////////////////////////////////////////
  Running: step = 3   Time: 17:56   Date: 2022-12-06 (elapsed time: 0d:0h:0m)
\\\\\\\\\\\\\\\\\\\\\\\\\\\\\\\\\\\\\\\\\\\\\\\\\\\\\\\\\\\\\\\\\\\\\\\\\\\\\\\\
==> Current working directory: '/opt2/data'
printf \
"homo_sapiens"  \
> /opt2/data/organism.txt
--------------------------------------------------------------------------------
+-->EXECUTING...
--------------------------------------------------------------------------------
==> Execution time: 0 day(s), 0 hour(s), 0 minute(s), and 0 second(s)
////////////////////////////////////////////////////////////////////////////////
  Running: step = 4   Time: 17:56   Date: 2022-12-06 (elapsed time: 0d:0h:0m)
\\\\\\\\\\\\\\\\\\\\\\\\\\\\\\\\\\\\\\\\\\\\\\\\\\\\\\\\\\\\\\\\\\\\\\\\\\\\\\\\
==> Current working directory: '/opt2/data'
get_genome.py \
--organism homo_sapiens \
--server ftp.ensembl.org \
--output /opt2/data/
--------------------------------------------------------------------------------
+-->EXECUTING...
--------------------------------------------------------------------------------
==> Execution time: 0 day(s), 0 hour(s), 0 minute(s), and 43 second(s)
////////////////////////////////////////////////////////////////////////////////
  Running: step = 5   Time: 17:57   Date: 2022-12-06 (elapsed time: 0d:0h:1m)
\\\\\\\\\\\\\\\\\\\\\\\\\\\\\\\\\\\\\\\\\\\\\\\\\\\\\\\\\\\\\\\\\\\\\\\\\\\\\\\\
==> Current working directory: '/opt2/data'
generate_chrom_lens.py \
--input_genome /opt2/data/genome.fa \
--output /opt2/data/
--------------------------------------------------------------------------------
+-->EXECUTING...
--------------------------------------------------------------------------------
==> Execution time: 0 day(s), 0 hour(s), 0 minute(s), and 10 second(s)
////////////////////////////////////////////////////////////////////////////////
  Running: step = 6   Time: 17:57   Date: 2022-12-06 (elapsed time: 0d:0h:1m)
\\\\\\\\\\\\\\\\\\\\\\\\\\\\\\\\\\\\\\\\\\\\\\\\\\\\\\\\\\\\\\\\\\\\\\\\\\\\\\\\
==> Current working directory: '/opt2/data'
get_gtf.py \
--organism homo_sapiens \
--server ftp.ensembl.org \
--output /opt2/data/
--------------------------------------------------------------------------------
+-->EXECUTING...


ERROR: Workflow execution failed at step 6 while executing:
----------------
   get_gtf.py \
   --organism homo_sapiens \
   --server ftp.ensembl.org \
   --output /opt2/data/
----------------


Executing second time the same step/command in order to capture error messages (i.e. STDERR)...

-------------------------------------------
[91mTraceback (most recent call last):
  File "/opt2/conda/envs/fusioncatcher/bin/fusioncatcher-build.py", line 493, in <module>
[0m[91m    job.run()
  File "/opt2/conda/envs/fusioncatcher/bin/workflow.py", line 978, in run
[0m[91m    temp_file = self.__give_me_temp_filename()
  File "/opt2/conda/envs/fusioncatcher/bin/workflow.py", line 1881, in __give_me_temp_filename
    (ft,ft_name) = tempfile.mkstemp(dir = tmp_dir)
  File "/opt2/conda/envs/fusioncatcher/lib/python2.7/tempfile.py", line 307, in mkstemp
[0m[91m    [0m[91mdir = gettempdir()
[0m[91m  File "/opt2/conda/envs/fusioncatcher/lib/python2.7/tempfile.py", line 275, in gettempdir
[0m[91m    [0m[91mtempdir = _get_default_tempdir()
[0m[91m  File "/opt2/conda/envs/fusioncatcher/lib/python2.7/tempfile.py", line 217, in _get_default_tempdir
[0m[91m    [0m[91m("No usable temporary directory found in %s" % dirlist))
[0m[91mIOError[0m[91m: [0m[91m[Errno 2] No usable temporary directory found in ['/tmp', '/var/tmp', '/usr/tmp', '/opt2/data'][0m[91m
[0m[91mclose failed in file object destructor:
IOError: [Errno 28] No space left on device
[0m################################################################################
################################################################################
TOTAL RUNNING TIME: 0 day(s), 0 hour(s), 1 minute(s), and 8 second(s) 
################################################################################
################################################################################
